INFO:__main__:Initializing service
INFO:__main__:Starting call to '__main__.init', this is the 1st time calling it.
ERROR:__main__:HTTPConnectionPool(host='src-backend-1', port=80): Max retries exceeded with url: /api/api_v1/modifier/ (Caused by NewConnectionError('<urllib3.connection.HTTPConnection object at 0x7f81af04ef10>: Failed to establish a new connection: [Errno 111] Connection refused'))
WARNING:__main__:Finished call to '__main__.init' after 0.004(s), this was the 1st time calling it.
INFO:__main__:Starting call to '__main__.init', this is the 2nd time calling it.
ERROR:__main__:HTTPConnectionPool(host='src-backend-1', port=80): Max retries exceeded with url: /api/api_v1/modifier/ (Caused by NewConnectionError('<urllib3.connection.HTTPConnection object at 0x7f81af060cd0>: Failed to establish a new connection: [Errno 111] Connection refused'))
WARNING:__main__:Finished call to '__main__.init' after 1.006(s), this was the 2nd time calling it.
INFO:__main__:Starting call to '__main__.init', this is the 3rd time calling it.
ERROR:__main__:HTTPConnectionPool(host='src-backend-1', port=80): Max retries exceeded with url: /api/api_v1/modifier/ (Caused by NewConnectionError('<urllib3.connection.HTTPConnection object at 0x7f81af0628d0>: Failed to establish a new connection: [Errno 111] Connection refused'))
WARNING:__main__:Finished call to '__main__.init' after 2.008(s), this was the 3rd time calling it.
INFO:__main__:Starting call to '__main__.init', this is the 4th time calling it.
ERROR:__main__:HTTPConnectionPool(host='src-backend-1', port=80): Max retries exceeded with url: /api/api_v1/modifier/ (Caused by NewConnectionError('<urllib3.connection.HTTPConnection object at 0x7f81af04e9d0>: Failed to establish a new connection: [Errno 111] Connection refused'))
WARNING:__main__:Finished call to '__main__.init' after 3.010(s), this was the 4th time calling it.
INFO:__main__:Starting call to '__main__.init', this is the 5th time calling it.
ERROR:__main__:HTTPConnectionPool(host='src-backend-1', port=80): Max retries exceeded with url: /api/api_v1/modifier/ (Caused by NewConnectionError('<urllib3.connection.HTTPConnection object at 0x7f81af061f10>: Failed to establish a new connection: [Errno 111] Connection refused'))
WARNING:__main__:Finished call to '__main__.init' after 4.011(s), this was the 5th time calling it.
INFO:__main__:Starting call to '__main__.init', this is the 6th time calling it.
INFO:__main__:Service finished initializing
INFO:__main__:Initializing service
INFO:__main__:Starting call to '__main__.init', this is the 1st time calling it.
INFO:__main__:Service finished initializing
INFO:__main__:Initializing service
INFO:__main__:Starting call to '__main__.init', this is the 1st time calling it.
INFO:__main__:Service finished initializing
INFO:__main__:Initializing service
INFO:__main__:Starting call to '__main__.init', this is the 1st time calling it.
INFO:__main__:Service finished initializing
INFO:__main__:Initializing service
INFO:__main__:Starting call to '__main__.init', this is the 1st time calling it.
INFO:__main__:Service finished initializing
